Traceback (most recent call last):
  File "/mnt/lustre/home/jablasco/yelmo-ucm/yelmox_v1.5/./runylmox", line 572, in <module>
    main()
  File "/mnt/lustre/home/jablasco/yelmo-ucm/yelmox_v1.5/./runylmox", line 315, in main
    run_info['git hash'] = get_git_revision_hash()
  File "/mnt/lustre/home/jablasco/yelmo-ucm/yelmox_v1.5/./runylmox", line 507, in get_git_revision_hash
    githash = subp.check_output(['git', 'rev-parse', 'HEAD']).strip()
  File "/home/jablasco/miniconda3/lib/python3.9/subprocess.py", line 424, in check_output
    return run(*popenargs, stdout=PIPE, timeout=timeout, check=True,
  File "/home/jablasco/miniconda3/lib/python3.9/subprocess.py", line 505, in run
    with Popen(*popenargs, **kwargs) as process:
  File "/home/jablasco/miniconda3/lib/python3.9/subprocess.py", line 951, in __init__
    self._execute_child(args, executable, preexec_fn, close_fds,
  File "/home/jablasco/miniconda3/lib/python3.9/subprocess.py", line 1821, in _execute_child
    raise child_exception_type(errno_num, err_msg, err_filename)
FileNotFoundError: [Errno 2] No such file or directory: 'git'
